<?xml version="1.0"?>

<robot xmlns:xacro="http://www.ros.org/wiki/xacro" name="bumperbot">
  <!-- 적절한 ros2 control library를 가져오기 위한 변수. ros2 버전에 따라 다른 플러그인을 사용. -->
  <xacro:arg name ="is_ignition" default="false"/>

  <!-- gazebo params -->
  <xacro:include filename="$(find bumperbot_description)/urdf/bumperbot_gazebo.xacro"/>
  <!-- ros2 control lib -->
  <xacro:include filename="$(find bumperbot_description)/urdf/bumperbot_ros2_control.xacro"/>

  <!-- 외부 - 로봇 사이를 연결하는 일종의 인터페이스 역할 -->
  <link name="base_footprint" />
  <!-- 실제 로봇 역할 -->
  <link name="base_link">
    <inertial>
      <origin xyz="0 0 0.04" rpy="0.0 0.25 0.3" />
      <mass value="8.2573504e-01" />
      <inertia ixx="2.2124416e-02" ixy="-1.2294101e-04" ixz="3.4938785e-04"
        iyy="2.1193702e-02" iyz="-5.0120904e-05" izz="2.0064271e-02"
      />
    </inertial>
    <visual>
      <!-- 시각 측면에서 메시의 각도 및 좌표. rpy = 각도, xyz = 좌표 -->
      <origin rpy="0.0 0.0 0.0" xyz="0.0 0.0 0.0" />
      <geometry>
        <!-- 메시 파일 위치 -->
        <mesh filename="package://bumperbot_description/meshes/base_link.STL" />
      </geometry>
    </visual>
    <collision>
      <origin rpy="0.0 0.0 0.0" xyz="0.0 0.0 0.0" />
      <geometry>
        <!-- 메시 파일 위치 -->
        <mesh filename="package://bumperbot_description/meshes/base_link.STL" />
      </geometry>
    </collision>
  </link>

  <joint name="base_joint" type="fixed">
    <parent link="base_footprint" />
    <child link="base_link" />
    <!-- parent에 대한 child의 상대 각도 / 위치 -->
    <origin rpy="0.0 0.0 0.0" xyz="0.0 0.0 0.033" />
  </joint>

  <link name="wheel_right_link">
    <inertial>
      <origin xyz="0 -0.014 0" rpy="0 0 0" />
      <mass value="0.0530086090966721" />
      <inertia ixx="1.88176298336665E-05" ixy="-4.8444933029987E-10" ixz="1.88163708851143E-08"
        iyy="3.11510738647764E-05" iyz="-6.93560663069607E-11" izz="1.8801969558182E-05"
      />
    </inertial>
    <visual>
      <origin rpy="1.57 0 0" xyz="0 0 0" />
      <geometry>
        <mesh filename="package://bumperbot_description/meshes/wheel_right_link.STL" />
      </geometry>
    </visual>
    <!-- collider != mesh -->
    <collision>
      <origin rpy="1.57 0 0" xyz="0 -0.015 0" />
      <geometry>
        <sphere radius="0.033" />
      </geometry>
    </collision>
  </link>
  <!-- continous => rollable -->
  <joint name="wheel_right_joint" type="continuous">
    <parent link="base_link" />
    <child link="wheel_right_link" />
    <!-- y축 -->
    <axis xyz="0 1 0" />
    <origin rpy="0.0 0.0 0.0" xyz="0.0 -0.07 0.0" />
  </joint>

  <link name="wheel_left_link">
    <inertial>
      <origin xyz="0 0.014 0" rpy="0 0 0" />
      <mass value="0.0530086043217644" />
      <inertia ixx="1.8792911368909E-05"  ixy="3.31256392204584E-10" ixz="-1.14082001662767E-08"
               iyy="3.11510738759073E-05" iyz="-3.60499245082192E-10"
               izz="1.88266886146847E-05" />
    </inertial>
    <visual>
      <origin rpy="-1.57 0 0" xyz="0 0 0" />
      <geometry>
        <mesh filename="package://bumperbot_description/meshes/wheel_left_link.STL" />
      </geometry>
    </visual>
    <collision>
      <origin rpy="1.57 0 0" xyz="0 0.015 0" />
      <geometry>
        <sphere radius="0.033" />
      </geometry>
    </collision>
  </link>
  <!-- continous => rollable -->
  <joint name="wheel_left_joint" type="continuous">
    <parent link="base_link" />
    <child link="wheel_left_link" />
    <!-- y축 -->
    <axis xyz="0 1 0" />
    <origin rpy="0.0 0.0 0.0" xyz="0.0 0.07 0.0" />
  </joint>

  <link name="caster_front_link">
    <inertia ixx="7.23075276010246E-11" ixy="-6.10956883467859E-16" ixz="2.22849693525031E-15"
               iyy="3.8713793085917E-11"  iyz="2.93909858781952E-15"
               izz="1.00967486676306E-10" />
    <visual>
      <origin rpy="0.0 0.0 0.0" xyz="0 0 0" />
      <geometry>
        <mesh filename="package://bumperbot_description/meshes/caster_front_link.STL" />
      </geometry>
    </visual>
    <collision>
      <origin rpy="0 0 0" xyz="0 0 0" />
      <geometry>
        <sphere radius="0.005" />
      </geometry>
    </collision>
  </link>

  <joint name="caster_front_joint" type="fixed">
    <parent link="base_link" />
    <child link="caster_front_link" />
    <origin rpy="0.0 0.0 0.0" xyz="0.04755 0.0 -0.0275" />
  </joint>

  <link name="caster_rear_link">
    <inertia ixx="7.23075276010246E-11" ixy="-6.10956872363424E-16" ixz="2.22849693527207E-15"
    iyy="3.87137930859167E-11" iyz="2.939098587861E-15"
    izz="1.00967486676306E-10" />
    <visual>
      <origin rpy="0.0 0.0 0.0" xyz="0 0 0" />
      <geometry>
        <mesh filename="package://bumperbot_description/meshes/caster_rear_link.STL" />
      </geometry>
    </visual>
    <!-- visual == volume. not all case. -->
    <collision>
      <origin rpy="0 0 0" xyz="0 0 0" />
      <geometry>
        <sphere radius="0.005" />
      </geometry>
    </collision>
  </link>

  <joint name="caster_rear_joint" type="fixed">
    <parent link="base_link" />
    <child link="caster_rear_link" />
    <origin rpy="0.0 0.0 0.0" xyz="-0.04755 0.0 -0.0275" />
  </joint>

  <link name="can_link">
    <visual>
      <origin rpy="1.57 0.0 0.0" xyz="-0.0321 0.0321 0.0" />
      <geometry>
        <mesh filename="package://bumperbot_description/meshes/can.STL" />
      </geometry>
    </visual>
  </link>

  <joint name="can_joint" type="fixed">
    <parent link="base_link" />
    <child link="can_link" />
    <!-- checked by blender -->
    <origin rpy="0.0 0.0 0.0" xyz="0 0 0.08" />
  </joint>
</robot>